Workbook
Name APIdapter_CCP_B: 'Program Config'!#REF!
Name Back_To_Build_Specs: 'Program Config'!$C$33
Name CCP: 'Program Config'!#REF!
Name Client_URL: 'Program Config'!$C$34
Name Go_Back_to_Build_Specs: 'DemoData3 CCP Tab'!$C$1
Name Link_Back_To_Build_Specs: 'Program Config'!$C$34
Name Link_to_APIdapter_Common_Custom_Parameters: 'Program Config'!$H$33
Name Time_Zone_Map: 'Program Config'!$B$2024

Sheet Program Contacts & Kickoff
A1: Implementation Manager | B1: Victoria Lane | E1: =IFERROR(IF(AND($B1<>"",VLOOKUP($B1,$O:$P,2,FALSE)<>""),VLOOKUP($B1,$O:$P,2,FALSE),$B1),IF($B1<>"",$B1,"")) -> victoria.lane@FakeDemoData.com | N1: Group | O1: Contact | P1: PRODCUT4 | Q1: Initials
A2: Customer Success Manager | B2: Leah Adler | E2: =IFERROR(IF(AND($B2<>"",VLOOKUP($B2,$O:$P,2,FALSE)<>""),VLOOKUP($B2,$O:$P,2,FALSE),$B2),IF($B2<>"",$B2,"")) -> leah.adler@FakeDemoData.com | N2: CSM | O2: Ava Mitchell | P2: ava.mitchell@FakeDemoData.com | Q2: AM
A3: Sales Representative | B3: Gavin Park | E3: =IFERROR(IF(AND($B3<>"",VLOOKUP($B3,$O:$P,2,FALSE)<>""),VLOOKUP($B3,$O:$P,2,FALSE),$B3),IF($B3<>"",$B3,"")) -> gavin.park@FakeDemoData.com | N3: CSM | O3: Liam Carter | P3: liam.carter@FakeDemoData.com | Q3: LC
N4: IM | O4: Sofia Ramirez | P4: sofia.ramirez@FakeDemoData.com | Q4: SR
B5: Contact PRODCUT4 | C5: Contact Category | D5: Primary | H5: All PRODCUT4 | I5: Full Name | J5: First Name | K5: Second Name | L5: L,F | N5: CSM | O5: Noah Bennett | P5: noah.bennett@FakeDemoData.com | Q5: NB | R5: New! Primary Radial & All PRODCUT4 Check Boxes!
A6: Identify additional people who should be copied on program PRODCUT4 (including client PRODCUT4 addresses): | B6: w.barnes@demodata.com | C6: Technical Contact | D6: 3 | E6: =IFERROR(IF(AND($B6<>"",VLOOKUP($B6,$O:$P,2,FALSE)<>""),VLOOKUP($B6,$O:$P,2,FALSE),$B6),IF($B6<>"",$B6,"")) -> w.barnes@demodata.com | H6: TRUE | I6: =_xlfn.TEXTJOIN(" ",TRUE,J6,K6) -> William Barnes | J6: {=IFERROR(IF(AND($B$16<>"",$H$16<>""),_xlfn.LET( _xlpm.result, IF($H$16="First Name", INDEX($E$18:$E$27,MATCH(TRUE,INDEX(ISNUMBER(SEARCH(LOWER($E$18:$E$27),LOWER(B6))),0),0)), INDEX($E$18:$E$27,MATCH(TRUE,INDEX(ISNUMBER(SEARCH(LOWER($F$18:$F$27),LOWER(B6))),0),0)) ), IF(_xlpm.result=0,"",_xlpm.result) ),""),"")} -> William | K6: {=IFERROR(IF(AND($B$16<>"",$H$16<>""), _xlfn.LET( _xlpm.result, IF($H$16="Second Name", INDEX($F$18:$F$27,MATCH(TRUE,INDEX(ISNUMBER(SEARCH(LOWER($F$18:$F$27),LOWER(B6))),0),0)), INDEX($E$18:$E$27,MATCH(TRUE,INDEX(ISNUMBER(SEARCH(LOWER($E$18:$E$27),LOWER(B6))),0),0)) ), IF(_xlpm.result=0,"",_xlpm.result) ), ""),"")} -> Barnes | L6: =_xlfn.TEXTJOIN(", ",TRUE,K6,J6) -> Barnes, William | N6: Sales | O6: Mia Thompson | P6: mia.thompson@FakeDemoData.com | Q6: MT | S6: Choosing a primary contact will populate their information on the LK Frontloader Tab
B7: m.chen@demodata.com | C7: JLB (Not on List) | D7: 1 | E7: =IFERROR(IF(AND($B7<>"",VLOOKUP($B7,$O:$P,2,FALSE)<>""),VLOOKUP($B7,$O:$P,2,FALSE),$B7),IF($B7<>"",$B7,"")) -> m.chen@demodata.com | H7: FALSE | I7: =_xlfn.TEXTJOIN(" ",TRUE,J7,K7) -> Maya Chen | J7: {=IFERROR(IF(AND($B$16<>"",$H$16<>""),_xlfn.LET( _xlpm.result, IF($H$16="First Name", INDEX($E$18:$E$27,MATCH(TRUE,INDEX(ISNUMBER(SEARCH(LOWER($E$18:$E$27),LOWER(B7))),0),0)), INDEX($E$18:$E$27,MATCH(TRUE,INDEX(ISNUMBER(SEARCH(LOWER($F$18:$F$27),LOWER(B7))),0),0)) ), IF(_xlpm.result=0,"",_xlpm.result) ),""),"")} -> Maya | K7: {=IFERROR(IF(AND($B$16<>"",$H$16<>""), _xlfn.LET( _xlpm.result, IF($H$16="Second Name", INDEX($F$18:$F$27,MATCH(TRUE,INDEX(ISNUMBER(SEARCH(LOWER($F$18:$F$27),LOWER(B7))),0),0)), INDEX($E$18:$E$27,MATCH(TRUE,INDEX(ISNUMBER(SEARCH(LOWER($E$18:$E$27),LOWER(B7))),0),0)) ), IF(_xlpm.result=0,"",_xlpm.result) ), ""),"")} -> Chen | L7: =_xlfn.TEXTJOIN(", ",TRUE,K7,J7) -> Chen, Maya | N7: IM | O7: Jackson Hughes | P7: jackson.hughes@FakeDemoData.com | Q7: JH
A8: • Enter up to 10 PRODCUT4 addresses OR names | B8: t.navarro@demodata.com | C8: Program Contact | E8: =IFERROR(IF(AND($B8<>"",VLOOKUP($B8,$O:$P,2,FALSE)<>""),VLOOKUP($B8,$O:$P,2,FALSE),$B8),IF($B8<>"",$B8,"")) -> t.navarro@demodata.com | H8: TRUE | I8: =_xlfn.TEXTJOIN(" ",TRUE,J8,K8) -> Theo Navarro | J8: {=IFERROR(IF(AND($B$16<>"",$H$16<>""),_xlfn.LET( _xlpm.result, IF($H$16="First Name", INDEX($E$18:$E$27,MATCH(TRUE,INDEX(ISNUMBER(SEARCH(LOWER($E$18:$E$27),LOWER(B8))),0),0)), INDEX($E$18:$E$27,MATCH(TRUE,INDEX(ISNUMBER(SEARCH(LOWER($F$18:$F$27),LOWER(B8))),0),0)) ), IF(_xlpm.result=0,"",_xlpm.result) ),""),"")} -> Theo | K8: {=IFERROR(IF(AND($B$16<>"",$H$16<>""), _xlfn.LET( _xlpm.result, IF($H$16="Second Name", INDEX($F$18:$F$27,MATCH(TRUE,INDEX(ISNUMBER(SEARCH(LOWER($F$18:$F$27),LOWER(B8))),0),0)), INDEX($E$18:$E$27,MATCH(TRUE,INDEX(ISNUMBER(SEARCH(LOWER($E$18:$E$27),LOWER(B8))),0),0)) ), IF(_xlpm.result=0,"",_xlpm.result) ), ""),"")} -> Navarro | L8: =_xlfn.TEXTJOIN(", ",TRUE,K8,J8) -> Navarro, Theo | N8: IM | O8: Isabella Flores | P8: isabella.flores@FakeDemoData.com | Q8: IF
A9: • @DemoData.com & @demodata.com PRODCUT4 will automagically be added to all PRODCUT4 CCs & Tags | B9: n.reed@demodata.com | C9: Program Contact | E9: =IFERROR(IF(AND($B9<>"",VLOOKUP($B9,$O:$P,2,FALSE)<>""),VLOOKUP($B9,$O:$P,2,FALSE),$B9),IF($B9<>"",$B9,"")) -> n.reed@demodata.com | H9: TRUE | I9: =_xlfn.TEXTJOIN(" ",TRUE,J9,K9) -> Noaln Reed | J9: {=IFERROR(IF(AND($B$16<>"",$H$16<>""),_xlfn.LET( _xlpm.result, IF($H$16="First Name", INDEX($E$18:$E$27,MATCH(TRUE,INDEX(ISNUMBER(SEARCH(LOWER($E$18:$E$27),LOWER(B9))),0),0)), INDEX($E$18:$E$27,MATCH(TRUE,INDEX(ISNUMBER(SEARCH(LOWER($F$18:$F$27),LOWER(B9))),0),0)) ), IF(_xlpm.result=0,"",_xlpm.result) ),""),"")} -> Noaln | K9: {=IFERROR(IF(AND($B$16<>"",$H$16<>""), _xlfn.LET( _xlpm.result, IF($H$16="Second Name", INDEX($F$18:$F$27,MATCH(TRUE,INDEX(ISNUMBER(SEARCH(LOWER($F$18:$F$27),LOWER(B9))),0),0)), INDEX($E$18:$E$27,MATCH(TRUE,INDEX(ISNUMBER(SEARCH(LOWER($E$18:$E$27),LOWER(B9))),0),0)) ), IF(_xlpm.result=0,"",_xlpm.result) ), ""),"")} -> Reed | L9: =_xlfn.TEXTJOIN(", ",TRUE,K9,J9) -> Reed, Noaln | N9: Sales | O9: Lucas Morgan | P9: lucas.morgan@FakeDemoData.com | Q9: LM
E10: =IFERROR(IF(AND($B10<>"",VLOOKUP($B10,$O:$P,2,FALSE)<>""),VLOOKUP($B10,$O:$P,2,FALSE),$B10),IF($B10<>"",$B10,"")) | H10: FALSE | I10: =_xlfn.TEXTJOIN(" ",TRUE,J10,K10) | J10: {=IFERROR(IF(AND($B$16<>"",$H$16<>""),_xlfn.LET( _xlpm.result, IF($H$16="First Name", INDEX($E$18:$E$27,MATCH(TRUE,INDEX(ISNUMBER(SEARCH(LOWER($E$18:$E$27),LOWER(B10))),0),0)), INDEX($E$18:$E$27,MATCH(TRUE,INDEX(ISNUMBER(SEARCH(LOWER($F$18:$F$27),LOWER(B10))),0),0)) ), IF(_xlpm.result=0,"",_xlpm.result) ),""),"")} | K10: {=IFERROR(IF(AND($B$16<>"",$H$16<>""), _xlfn.LET( _xlpm.result, IF($H$16="Second Name", INDEX($F$18:$F$27,MATCH(TRUE,INDEX(ISNUMBER(SEARCH(LOWER($F$18:$F$27),LOWER(B10))),0),0)), INDEX($E$18:$E$27,MATCH(TRUE,INDEX(ISNUMBER(SEARCH(LOWER($E$18:$E$27),LOWER(B10))),0),0)) ), IF(_xlpm.result=0,"",_xlpm.result) ), ""),"")} | L10: =_xlfn.TEXTJOIN(", ",TRUE,K10,J10) | N10: CSM | O10: Charlotte Price | P10: charlotte.price@FakeDemoData.com | Q10: CP | R10: New! Client Name String & Matching Component!
A11: • All PRODCUT4 from other PRODUCT4 will be added to TO lines according to the Client Contact Type* selected from the drop down, see list below | E11: =IFERROR(IF(AND($B11<>"",VLOOKUP($B11,$O:$P,2,FALSE)<>""),VLOOKUP($B11,$O:$P,2,FALSE),$B11),IF($B11<>"",$B11,"")) | H11: FALSE | I11: =_xlfn.TEXTJOIN(" ",TRUE,J11,K11) | J11: {=IFERROR(IF(AND($B$16<>"",$H$16<>""),_xlfn.LET( _xlpm.result, IF($H$16="First Name", INDEX($E$18:$E$27,MATCH(TRUE,INDEX(ISNUMBER(SEARCH(LOWER($E$18:$E$27),LOWER(B11))),0),0)), INDEX($E$18:$E$27,MATCH(TRUE,INDEX(ISNUMBER(SEARCH(LOWER($F$18:$F$27),LOWER(B11))),0),0)) ), IF(_xlpm.result=0,"",_xlpm.result) ),""),"")} | K11: {=IFERROR(IF(AND($B$16<>"",$H$16<>""), _xlfn.LET( _xlpm.result, IF($H$16="Second Name", INDEX($F$18:$F$27,MATCH(TRUE,INDEX(ISNUMBER(SEARCH(LOWER($F$18:$F$27),LOWER(B11))),0),0)), INDEX($E$18:$E$27,MATCH(TRUE,INDEX(ISNUMBER(SEARCH(LOWER($E$18:$E$27),LOWER(B11))),0),0)) ), IF(_xlpm.result=0,"",_xlpm.result) ), ""),"")} | L11: =_xlfn.TEXTJOIN(", ",TRUE,K11,J11) | N11: Sales | O11: Ethan Rivera | P11: ethan.rivera@FakeDemoData.com | Q11: ER | S11: Dropping a text string of all client contacts & selecting if their first name or second names match their PRODCUT4 will populate their full names.
E12: =IFERROR(IF(AND($B12<>"",VLOOKUP($B12,$O:$P,2,FALSE)<>""),VLOOKUP($B12,$O:$P,2,FALSE),$B12),IF($B12<>"",$B12,"")) | H12: FALSE | I12: =_xlfn.TEXTJOIN(" ",TRUE,J12,K12) | J12: {=IFERROR(IF(AND($B$16<>"",$H$16<>""),_xlfn.LET( _xlpm.result, IF($H$16="First Name", INDEX($E$18:$E$27,MATCH(TRUE,INDEX(ISNUMBER(SEARCH(LOWER($E$18:$E$27),LOWER(B12))),0),0)), INDEX($E$18:$E$27,MATCH(TRUE,INDEX(ISNUMBER(SEARCH(LOWER($F$18:$F$27),LOWER(B12))),0),0)) ), IF(_xlpm.result=0,"",_xlpm.result) ),""),"")} | K12: {=IFERROR(IF(AND($B$16<>"",$H$16<>""), _xlfn.LET( _xlpm.result, IF($H$16="Second Name", INDEX($F$18:$F$27,MATCH(TRUE,INDEX(ISNUMBER(SEARCH(LOWER($F$18:$F$27),LOWER(B12))),0),0)), INDEX($E$18:$E$27,MATCH(TRUE,INDEX(ISNUMBER(SEARCH(LOWER($E$18:$E$27),LOWER(B12))),0),0)) ), IF(_xlpm.result=0,"",_xlpm.result) ), ""),"")} | L12: =_xlfn.TEXTJOIN(", ",TRUE,K12,J12) | N12: CSM | O12: Amelia Howard | P12: amelia.howard@FakeDemoData.com | Q12: AH
A13: Technical Contact --> Integration / Migration + Whitelist + Rostering/PRODUCT2 Program Contact --> Program Preferences All Client PRODCUT4 --> All Client PRODCUT4 | E13: =IFERROR(IF(AND($B13<>"",VLOOKUP($B13,$O:$P,2,FALSE)<>""),VLOOKUP($B13,$O:$P,2,FALSE),$B13),IF($B13<>"",$B13,"")) | H13: FALSE | I13: =_xlfn.TEXTJOIN(" ",TRUE,J13,K13) | J13: {=IFERROR(IF(AND($B$16<>"",$H$16<>""),_xlfn.LET( _xlpm.result, IF($H$16="First Name", INDEX($E$18:$E$27,MATCH(TRUE,INDEX(ISNUMBER(SEARCH(LOWER($E$18:$E$27),LOWER(B13))),0),0)), INDEX($E$18:$E$27,MATCH(TRUE,INDEX(ISNUMBER(SEARCH(LOWER($F$18:$F$27),LOWER(B13))),0),0)) ), IF(_xlpm.result=0,"",_xlpm.result) ),""),"")} | K13: {=IFERROR(IF(AND($B$16<>"",$H$16<>""), _xlfn.LET( _xlpm.result, IF($H$16="Second Name", INDEX($F$18:$F$27,MATCH(TRUE,INDEX(ISNUMBER(SEARCH(LOWER($F$18:$F$27),LOWER(B13))),0),0)), INDEX($E$18:$E$27,MATCH(TRUE,INDEX(ISNUMBER(SEARCH(LOWER($E$18:$E$27),LOWER(B13))),0),0)) ), IF(_xlpm.result=0,"",_xlpm.result) ), ""),"")} | L13: =_xlfn.TEXTJOIN(", ",TRUE,K13,J13) | N13: CSM | O13: Oliver Brooks | P13: oliver.brooks@FakeDemoData.com | Q13: OB
E14: =IFERROR(IF(AND($B14<>"",VLOOKUP($B14,$O:$P,2,FALSE)<>""),VLOOKUP($B14,$O:$P,2,FALSE),$B14),IF($B14<>"",$B14,"")) | H14: FALSE | I14: =_xlfn.TEXTJOIN(" ",TRUE,J14,K14) | J14: {=IFERROR(IF(AND($B$16<>"",$H$16<>""),_xlfn.LET( _xlpm.result, IF($H$16="First Name", INDEX($E$18:$E$27,MATCH(TRUE,INDEX(ISNUMBER(SEARCH(LOWER($E$18:$E$27),LOWER(B14))),0),0)), INDEX($E$18:$E$27,MATCH(TRUE,INDEX(ISNUMBER(SEARCH(LOWER($F$18:$F$27),LOWER(B14))),0),0)) ), IF(_xlpm.result=0,"",_xlpm.result) ),""),"")} | K14: {=IFERROR(IF(AND($B$16<>"",$H$16<>""), _xlfn.LET( _xlpm.result, IF($H$16="Second Name", INDEX($F$18:$F$27,MATCH(TRUE,INDEX(ISNUMBER(SEARCH(LOWER($F$18:$F$27),LOWER(B14))),0),0)), INDEX($E$18:$E$27,MATCH(TRUE,INDEX(ISNUMBER(SEARCH(LOWER($E$18:$E$27),LOWER(B14))),0),0)) ), IF(_xlpm.result=0,"",_xlpm.result) ), ""),"")} | L14: =_xlfn.TEXTJOIN(", ",TRUE,K14,J14) | N14: Sales | O14: Harper Sloan | P14: harper.sloan@FakeDemoData.com | Q14: HS | S14: Pro Tip: Grab client PRODCUT4 and names string from the meeting invite in the Outlook Schedule Assistant.
A15: *If no Client Contact Type is selected and the PRODUCT4 is not @DemoData.com or @demodata.com, the contact will be added to all client PRODCUT4 | E15: =IFERROR(IF(AND($B15<>"",VLOOKUP($B15,$O:$P,2,FALSE)<>""),VLOOKUP($B15,$O:$P,2,FALSE),$B15),IF($B15<>"",$B15,"")) | H15: FALSE | I15: =_xlfn.TEXTJOIN(" ",TRUE,J15,K15) | J15: {=IFERROR(IF(AND($B$16<>"",$H$16<>""),_xlfn.LET( _xlpm.result, IF($H$16="First Name", INDEX($E$18:$E$27,MATCH(TRUE,INDEX(ISNUMBER(SEARCH(LOWER($E$18:$E$27),LOWER(B15))),0),0)), INDEX($E$18:$E$27,MATCH(TRUE,INDEX(ISNUMBER(SEARCH(LOWER($F$18:$F$27),LOWER(B15))),0),0)) ), IF(_xlpm.result=0,"",_xlpm.result) ),""),"")} | K15: {=IFERROR(IF(AND($B$16<>"",$H$16<>""), _xlfn.LET( _xlpm.result, IF($H$16="Second Name", INDEX($F$18:$F$27,MATCH(TRUE,INDEX(ISNUMBER(SEARCH(LOWER($F$18:$F$27),LOWER(B15))),0),0)), INDEX($E$18:$E$27,MATCH(TRUE,INDEX(ISNUMBER(SEARCH(LOWER($E$18:$E$27),LOWER(B15))),0),0)) ), IF(_xlpm.result=0,"",_xlpm.result) ), ""),"")} | L15: =_xlfn.TEXTJOIN(", ",TRUE,K15,J15) | N15: CSM | O15: Elijah Myers | P15: elijah.myers@FakeDemoData.com | Q15: EM
A16: Paste Client Names String & Select Matching Component | B16: Barnes,William; Chen, Maya; Navarro,Theo; Reed,Noaln; | H16: Second Name | N16: CSM | O16: Evelyn Grant | P16: evelyn.grant@FakeDemoData.com | Q16: EG
E17: FN | F17: LN | G17: Full Name | N17: IM | O17: Jameson Cole | P17: jameson.cole@FakeDemoData.com | Q17: JC | R17: Note: If client PRODCUT4 do not use either first or second name, you can still use the client name string and then manually assign each full name from the drop-down menu. The auto populate formula will not work once a select is made from the drop-down menu.
A18: Kick Off Call PRODUCT4 ls (If Known) | E18: {=_xlfn.LET( _xlpm.names, _xlfn.TEXTSPLIT($B$16,, ";", TRUE), _xlpm.trimmed, TRIM(_xlpm.names), _xlpm.fixed, IF(ISNUMBER(SEARCH(",", _xlpm.trimmed)), TRIM(_xlfn.TEXTAFTER(_xlpm.trimmed, ",") & " " & _xlfn.TEXTBEFORE(_xlpm.trimmed, ",")), _xlpm.trimmed), _xlpm.first, _xlfn.TEXTBEFORE(_xlpm.fixed, " "), _xlpm.last, _xlfn.TEXTAFTER(_xlpm.fixed, " ", -1), _xlfn.HSTACK(_xlpm.first, _xlpm.last) )} -> William | F18: Barnes | G18: {=TRANSPOSE(_xlfn.TEXTSPLIT(B16,";",TRUE,TRUE))} -> Barnes,William | N18: CSM | O18: Scarlett Wells | P18: scarlett.wells@FakeDemoData.com | Q18: SW
A19: Date | B19: 46079 | E19: Maya | F19: Chen | G19: Chen, Maya | N19: CSM | O19: Benjamin Fox | P19: benjamin.fox@FakeDemoData.com | Q19: BF
A20: Time | B20: 1:00 PM EST | E20: Theo | F20: Navarro | G20: Navarro,Theo | N20: Sales | O20: Grace Turner | P20: grace.turner@FakeDemoData.com | Q20: GT
E21: Noaln | F21: Reed | G21: Reed,Noaln | N21: IM | O21: Michael Dawson | P21: michael.dawson@FakeDemoData.com | Q21: MD
A22: Most Recent Build Specs Edit: | B22: Updated on 2025-08-20 @ 9:23 AM by JLB | N22: Sales | O22: Lily DemoData2el | P22: lily.DemoData2el@FakeDemoData.com | Q22: LP
N23: IM | O23: Alexander Ruiz | P23: alexander.ruiz@FakeDemoData.com | Q23: AR
N24: CSM | O24: Chloe Kim | P24: chloe.kim@FakeDemoData.com | Q24: CK
N25: CSM | O25: Daniel Ortiz | P25: daniel.ortiz@FakeDemoData.com | Q25: DO
N26: Sales | O26: Zoe Parker | P26: zoe.parker@FakeDemoData.com | Q26: ZP
N27: Sales | O27: Matthew Stone | P27: matthew.stone@FakeDemoData.com | Q27: MS
E28: Primary Name | F28: =CHOOSE($D6,IF(I6<>"",I6,""),IF(I7<>"",I7,""),IF(I8<>"",I8,""),IF(I9<>"",I9,""),IF(I10<>"",I10,""),IF(I11<>"",I11,""),IF(I12<>"",I12,""),IF(I13<>"",I13,""),IF(I14<>"",I14,""),IF(I15<>"",I15,"")) -> Theo Navarro | N28: CSM | O28: Nora Greene | P28: nora.greene@FakeDemoData.com | Q28: NG
E29: Primary PRODCUT4 | F29: =CHOOSE($D6,IF(B6<>"",B6,""),IF(B7<>"",B7,""),IF(B8<>"",B8,""),IF(B9<>"",B9,""),IF(B10<>"",B10,""),IF(B11<>"",B11,""),IF(B12<>"",B12,""),IF(B13<>"",B13,""),IF(B14<>"",B14,""),IF(B15<>"",B15,"")) -> t.navarro@demodata.com | N29: IM | O29: Samuel Lowe | P29: samuel.lowe@FakeDemoData.com | Q29: SL
N30: CSM | O30: Audrey Kimball | P30: audrey.kimball@FakeDemoData.com | Q30: AK
N31: Sales | O31: William Barnes | P31: william.barnes@FakeDemoData.com | Q31: WB
N32: CSM | O32: Penelope Hart | P32: penelope.hart@FakeDemoData.com | Q32: PH
N33: Sales | O33: Henry Vega | P33: henry.vega@FakeDemoData.com | Q33: HV
N34: CSM | O34: Victoria Lane | P34: victoria.lane@FakeDemoData.com | Q34: VL
N35: CSM | O35: Caleb Bishop | P35: caleb.bishop@FakeDemoData.com | Q35: CB
N36: CSM | O36: Leah Adler | P36: leah.adler@FakeDemoData.com | Q36: LA
N37: Sales | O37: Owen Pratt | P37: owen.pratt@FakeDemoData.com | Q37: OP
N38: Sales | O38: Ruby Ellis | P38: ruby.ellis@FakeDemoData.com | Q38: RE
N39: CSM | O39: Gavin Park | P39: gavin.park@FakeDemoData.com | Q39: GP
N40: CSM | O40: Maya Chen | P40: maya.chen@FakeDemoData.com | Q40: MC
...

Sheet Program Config
A1: {=IF($C$8="","Client Build Specs",_xlfn.IFS($C$27=0,$C$8,$C$27="n/a",$C$8,$C$27>0,IFERROR(_xlfn.CONCAT(""&(C8)&IF(C27<>""," - "&($C$27),"")&IF(H2<>""," - "&(H2)&"")),"c8")))} -> INTEGRATION_AUTO_SHEET - 2026 - New Build | G1: Market: | H1: MARKET4 | I1: Platform: | J1: LATEST (Default) | M1: =IF(OR($L$2='Drop Down Lists'!$AV$20,$L$2='Drop Down Lists'!$AV$21,$L$2='Drop Down Lists'!$AV$22,$L$2='Drop Down Lists'!$AV$24,$L$2='Drop Down Lists'!$AV$23),"Pick Follow Up Date & Reason from Drop-Down Lists ⬇️⬇️","")
A2: Client Build Folder Link: | C2: https://www.linkedin.com/in/jo-ann-balsamo/ | G2: SPEC Type: | H2: New Build | L2: =IFERROR(VLOOKUP($I$2,'Drop Down Lists'!$AU$20:$AW$24,2,FALSE),IF(AND(I2="",I4<>""),'Drop Down Lists'!$AV$24,"")) | N2: =_xlfn.CONCAT(""&(TEXT(TODAY()+7,"YYYY-MM-DD"))&" - 1 Week") -> 2026-03-05 - 1 Week
A3: Client Build Specs Edit Link: | C3: https://www.linkedin.com/in/jo-ann-balsamo/ | G3: Build Specs View Only Link: | H3: https://www.linkedin.com/in/jo-ann-balsamo/ | N3: =_xlfn.CONCAT(""&(TEXT(TODAY()+14,"YYYY-MM-DD"))&" - 2 Weeks") -> 2026-03-12 - 2 Weeks
A4: DOC1 Data Source | C4: https://www.linkedin.com/in/jo-ann-balsamo/ | G4: =IF(OR($I$2="Ticket",$I$2="GENINTEGRATION 31 Migration",$J$14<>"",$J$14<>"n/a"),"JLB Ticket Link:", "") -> JLB Ticket Link: | L4: {=_xlfn.IFS(OR($L$2='Drop Down Lists'!$AV$20:$AV$24),_xlfn.CONCAT("Additional Notes / Comments to be included:"&"",""))} -> #N/A | N4: =_xlfn.CONCAT(""&(TEXT(TODAY()+21,"YYYY-MM-DD"))&" - 3 Weeks") -> 2026-03-19 - 3 Weeks
A5: =IF($H$2<>"New Build","CRM Account Link", "CRM Opportunity Link") -> CRM Opportunity Link | C5: https://www.linkedin.com/in/jo-ann-balsamo/ | G5: Program LK Link: | L5: =IFERROR(VLOOKUP($L$2,'Drop Down Lists'!$AV$20:$AW$24,2,FALSE),"") | N5: =_xlfn.CONCAT(""&(TEXT(TODAY()+30,"YYYY-MM-DD"))&" - 30 Days") -> 2026-03-28 - 30 Days
A6: =IF($H$2<>"New Build","DOC1 Link", "DOC1 Transfer Form Link") -> DOC1 Transfer Form Link | C6: https://www.linkedin.com/in/jo-ann-balsamo/ | G6: PRODUCT2 MARKET2 Link: | N6: =_xlfn.CONCAT(""&(TEXT(TODAY()+60,"YYYY-MM-DD"))&" - 60 Days") -> 2026-04-27 - 60 Days
N7: =_xlfn.CONCAT(""&(TEXT(TODAY()+90,"YYYY-MM-DD"))&" - 90 Days") -> 2026-05-27 - 90 Days
A8: Opportunity/File Name | C8: {=LEFT(MID(CELL("filename"),SEARCH("[",CELL("filename"))+1, SEARCH("]",CELL("filename"))-SEARCH("[",CELL("filename"))-1),LEN(MID(CELL("filename"),SEARCH("[",CELL("filename"))+1, SEARCH("]",CELL("filename"))-SEARCH("[",CELL("filename"))-1))-17)} -> INTEGRATION_AUTO_SHEET | G8: Product(s): | H8: PRODUCT2 | I8: Rostering: | J8: LMS3 Rostering + PROD7 | N8: Client Requested Date:
A9: Institution Name (Finance Name): | C9: JLB Integration DEMO | G9: User Name Formats: | H9: Type1 | I9: Provide User Name Format:
A10: DOC1/Account Name: | C10: DEMO | E10: Program Name & Default AP: | F10: =TRIM(IFERROR(IF(C10<>"", _xlfn.TEXTBEFORE(C10, "("), ""), C10)) -> DEMO | H10: New✨ Program Name, AP, & IPR | I10: www IPR: | J10: =TRIM(IFERROR(IF(AND(C10<>"",F10<>""),"0.0.0.0:255.255.255.255",""),"")) -> 0.0.0.0:255.255.255.255
A11: =HYPERLINK(_xlfn.CONCAT("https://www.google.com/search?q="&(SUBSTITUTE($C$8," ","+"))&"+Address"),"State") -> State | C11: Alabama (AL) | E11: =HYPERLINK(_xlfn.CONCAT("https://www.google.com/search?q="&(SUBSTITUTE($C$8," ","+"))&"+Address"),"Zip Code:") -> Zip Code:
A12: =HYPERLINK(_xlfn.CONCAT("https://www.google.com/search?q="&(SUBSTITUTE($C$9," ","+"))&"+Address"),"Client Homepage URL") -> Client Homepage URL | C12: https://www.linkedin.com/in/jo-ann-balsamo/ | E12: =IFERROR(IF($C$32="","AUTO /PUBLIC/:",$A$32),"/PUBLIC/") -> AUTO /PUBLIC/: | F12: =TRIM( IFERROR( IF($C$32<>"", IF(AND(LEFT($C$32,1)="/",RIGHT($C$32,1)="/"), $C$32, "/" & TRIM($C$32) & "/" ), IF(ISNUMBER(SEARCH("www.",$C$12)), "/" & _xlfn.TEXTBEFORE(_xlfn.TEXTAFTER($C$12,"www."),".") & "/", "/" & _xlfn.TEXTBEFORE(_xlfn.TEXTAFTER($C$12,"https://"),".") & "/" ) ), "") ) -> /linkedin/ | H12: New✨ The AUTO /PUBLIC/ will be generated from the client's URL; override this by entering a /PUBLIC/ in C32
A13: Time Zone | C13: (GMT -8.0) Pacific Time (US & Canada)
A14: Client Integration Method | C14: LMS1 - GENINTEGRATION 31 Link & Course NAV | E14: 3-Letter Initials: | G14: LMS/Launchpad Environment:
A15: JLB Contract | L15: {=_xlfn.IFS(OR($L$2='Drop Down Lists'!$AV$20:$AV$23),_xlfn.CONCAT("⬆️⬆️ Copy this note into you Outlook Calendar as a follow up reminder!")&IF(AND(I4<>"",L$16='Drop Down Lists'!$AV$24),_xlfn.CONCAT(" 📢 A simplified note is included below for JLB ⬇️⬇️"),""),TRUE,IF($L$2='Drop Down Lists'!$AV$24,"⬆️⬆️ Copy this note into your JLB Ticket"),"","")} -> FALSE
A16: Primary Contract Dates | C16: Start Date: | D16: 46023 | E16: End Date: | F16: 46387 | G16: Target Launch Date: | H16: 46081 | L16: =IF(AND($I$2<>"", $I$4<>""),'Drop Down Lists'!$AV$24,"")
A17: Primary Contract Group | Type | C17: Per Hour | F17: Contract Group Name | H17: User Session Limit | I17: User Session Timeframe | J17: Concurrent Session Cap | L17: =IFERROR(VLOOKUP($L$16,'Drop Down Lists'!$AV$24:$AW$24,2,FALSE),"")
A18: Revenue | C18: 100 | D18: =HYPERLINK("https://www.linkedin.com/in/jo-ann-balsamo","PAGE2:") -> PAGE2: | E18: No | F18: =TRIM(IF(AND($C$17="Sessions - Per Student",$C$20<>""),(_xlfn.CONCAT("^"&($C$20)&"$ License")),IF(AND($C$17="Sessions - Per Student",$C$18<>"",$C$19<>""),(_xlfn.CONCAT("^"&($C$18/$C$19)&"$ Student Licenses")),IF(AND($C$17="DemoData1 Sessions",$C$20<>""),(_xlfn.CONCAT("^"&($C$20)&"$ DemoData1 License Program")),IF(AND($C$17="DemoData1 Sessions",$C$18<>"",$C$19<>""),(_xlfn.CONCAT("^"&($C$18/$C$19)&"$ DemoData1 License Program")),IF(OR($C$17="Sessions - Contract 1",$C$17="Sessions - Site Licenses"),"Contract 1",IF($C$17="PRODUCT2","PRODUCT2",IF($C$17="Sessions - DemoDataPlus","DemoDataPlus",IF($C$17="Per Hour","Default",IF($C$17="Sessions - Per Student","Check Inputs for Number of Sessions",IF($C$17="DemoData1 Sessions","Check Inputs for Number of Enrollment",""))))))))))) -> Default | J18: =IF($C$17<>"",_xlfn.UNICHAR(9744), _xlfn.UNICHAR(9744)) -> ☐
A19: {=_xlfn.IFS(LEFT($C$17,8)="Sessions","Cost Per Session", $C$17="DemoData1 Sessions", "Cost Per Session",$C$17="Per Hour", "Cost Per Hour",$C$17="PRODUCT2", "",TRUE,"Cost Per Hour")} -> Cost Per Hour | C19: 1 | D19: Monthly Billing: | E19: No | F19: Revenue | G19: Start Date | End Date | H19: Type | I19: Target | J19: IsBilledMonthly
A20: {=_xlfn.IFS(LEFT($C$17,8)="Sessions","Number of Sessions", $C$17="DemoData1 Sessions", "Number of School Enrollment",$C$17="PRODUCT2","",$C$17="Per Hour", "Number of Hours",TRUE,"Number of Hours")} -> Number of Hours | C20: 100 | D20: PROD187: | E20: Yes | F20: =IF(AND($C$18<>"",$C$19<>"",$C$20<>"",$C$17<>"PRODUCT2"),IF(ROUND(SUM($C$19*$C$20),2)=ROUND(SUM($C$18),2),ROUND(SUM($C$18),2),_xlfn.CONCAT("Math is not mathing! Check "&($A$18)&", "&($A$19)&" & "&($A$20)&"")),IF($C$18<>"",ROUND(SUM($C$18),2),IF(AND($C$19<>"",$C$20<>"",$C$17<>"PRODUCT2"),($C$19*$C$20),_xlfn.CONCAT("You need data! Check "&IF($C$18="",_xlfn.CONCAT(""&($A$18),IF(AND($C$19="",$C$20=""),_xlfn.CONCAT(", "&($A$19)&" & "&($A$20)&""),IF(OR($C$19="",$C$20=""),_xlfn.CONCAT(" & "&IF($C$19="",$A$19,$A$20))))),IF(AND($C$19="",$C$20=""),_xlfn.CONCAT(""&($A$19)&" & "&($A$20)&""),IF(OR($C$19="",$C$20=""),_xlfn.CONCAT(""&IF($C$19="",$A$19,$A$20))))))))) -> 100 | G20: =TRIM(IF(AND($D$16<>"",$F$16<>""),_xlfn.CONCAT(""&TEXT($D$16,"mm/dd/yyy")&" | "&TEXT($F$16,"mm/dd/yyy")&""),"Check Dates")) -> 01/01/2026 | 12/31/2026 | H20: {=TRIM(_xlfn.IFS(LEFT($C$17,8)="Sessions","Per Session",$C$17="DemoData1 Sessions","Per Session",$C$17="PRODUCT2","Per Session",$C$17="Per Hour","Per Hour",$C$17="n/a","Check Type",TRUE,""))} -> Per Hour | I20: =TRIM(IF(AND($C$18<>"",$C$19<>"",$C$20<>"",$C$17<>"PRODUCT2",ROUND(SUM($C$19*$C$20),2)=ROUND(SUM($C$18),2),OR(LEFT($C$17,8)="Sessions",LEFT($C$17,5)="DemoData1")),ROUND(SUM($C$18/'Drop Down Lists'!$AV$2),2),IF(AND(LEFT($C$17,8)<>"Sessions",LEFT($C$17,5)<>"DemoData1",$C$20<>"",$C$18<>"",$C$19<>"",$C$17<>"PRODUCT2"),ROUND(SUM($C$20),2),IF(AND($C$18<>"",OR(LEFT($C$17,8)="Sessions",LEFT($C$17,5)="DemoData1")),ROUND(SUM($C$18/'Drop Down Lists'!$AV$2),2),IF(AND($C$20<>"",$C$19<>"",OR(LEFT($C$17,8)="Sessions",LEFT($C$17,5)="DemoData1")),ROUND(SUM($C$19*$C$20)/'Drop Down Lists'!$AV$2,2),IF(AND($C$20<>"",$C$17="Per Hour"),ROUND(SUM($C$20),2),IF(AND($C$17="PRODUCT2",$C$18<>""),ROUND(SUM($C$18/'Drop Down Lists'!$AV$2),2),IF(AND($C$18<>"",$C$19<>"",$C$17="Per Hour"),ROUND(SUM($C$18/$C$19),2),_xlfn.CONCAT("You need data! Check "&IF($C$18="",_xlfn.CONCAT(""&($A$18),IF(AND($C$19="",$C$20=""),_xlfn.CONCAT(", "&($A$19)&" & "&($A$20)&""),IF(OR($C$19="",$C$20=""),_xlfn.CONCAT(" & "&IF($C$19="",$A$19,$A$20))))),IF(AND($C$19="",$C$20=""),_xlfn.CONCAT(""&($A$19)&" & "&($A$20)&""),IF(OR($C$19="",$C$20=""),_xlfn.CONCAT(""&IF($C$19="",$A$19,$A$20)))))))))))))) -> 100 | J20: =IF($E$19="Yes", _xlfn.UNICHAR(9745),_xlfn.UNICHAR(9744)) -> ☐
A21: Secondary Contract Dates | C21: Start Date: | E21: End Date: | G21: Target Launch Date:
A22: Secondary Contract Group | Type | F22: Contract Group Name | H22: User Session Limit | I22: User Session Timeframe | J22: Concurrent Session Cap
A23: Revenue | D23: =HYPERLINK("https://www.linkedin.com/in/jo-ann-balsamo","PAGE2:") -> PAGE2: | F23: =IF(AND($C$22="Sessions - Per Student",$C$25<>""),(_xlfn.CONCAT("^"&($C$25)&"$ License")),IF(AND($C$22="Sessions - Per Student",$C$23<>"",$C$24<>""),(_xlfn.CONCAT("^"&($C$23/$C$24)&"$ License")),IF(AND($C$22="DemoData1 Sessions",$C$25<>""),(_xlfn.CONCAT("^"&($C$25)&"$ DemoData1 License Program")),IF(AND($C$22="DemoData1 Sessions",$C$23<>"",$C$24<>""),(_xlfn.CONCAT("^"&($C$23/$C$24)&"$ DemoData1 License Program")),IF(OR($C$22="Sessions - Advanced Per Year",$C$22="Sessions - Site Licenses"),"Contract 1",IF($C$22="PRODUCT2","PRODUCT2",IF($C$22="Sessions - DemoDataPlus","DemoDataPlus",IF($C$22="Per Hour","Default",IF($C$22="Sessions - Per Student","Check Inputs for Number of Sessions",IF($C$22="DemoData1 Sessions","Check Inputs for Number of Enrollment","")))))))))) | J23: =IF($C$22<>"",_xlfn.UNICHAR(9744), _xlfn.UNICHAR(9744)) -> ☐
A24: {=_xlfn.IFS(LEFT($C$22,8)="Sessions","Cost Per Session", $C$22="DemoData1 Sessions", "Cost Per Session",$C$22="PRODUCT2","",$C$22="Per Hour", "Cost Per Hour",TRUE,"Cost Per Hour")} -> Cost Per Hour | D24: Monthly Billing: | F24: Revenue | G24: Start Date | End Date | H24: Type | I24: Target | J24: IsBilledMonthly
A25: {=_xlfn.IFS(LEFT($C$22,8)="Sessions","Number of Sessions", $C$22="DemoData1 Sessions", "Number of School Enrollment",$C$22="PRODUCT2","",$C$22="Per Hour", "Number of Hours",TRUE,"Number of Hours")} -> Number of Hours | D25: PROD187: | F25: =IF(AND($C$23<>"",$C$24<>"",$C$25<>"",$C$22<>"PRODUCT2"),IF(ROUND(SUM($C$24*$C$25),2)=ROUND(SUM($C$23),2),ROUND(SUM($C$23),2),_xlfn.CONCAT("Math is not mathing! Check "&($A$23)&", "&($A$24)&" & "&($A$25)&"")),IF($C$23<>"",ROUND(SUM($C$23),2),IF(AND($C$24<>"",$C$25<>"",$C$22<>"PRODUCT2"),($C$24*$C$25),_xlfn.CONCAT("You need data! Check "&IF($C$23="",_xlfn.CONCAT(""&($A$23),IF(AND($C$24="",$C$25=""),_xlfn.CONCAT(", "&($A$24)&" & "&($A$25)&""),IF(OR($C$24="",$C$25=""),_xlfn.CONCAT(" & "&IF($C$24="",$A$24,$A$25))))),IF(AND($C$24="",$C$25=""),_xlfn.CONCAT(""&($A$24)&" & "&($A$25)&""),IF(OR($C$24="",$C$25=""),_xlfn.CONCAT(""&IF($C$24="",$A$24,$A$25))))))))) -> You need data! Check Revenue, Cost Per Hour & Number of Hours | G25: =IF(AND($D$21<>"",$F$21<>""),_xlfn.CONCAT(""&TEXT($D$21,"mm/dd/yyy")&" | "&TEXT($F$21,"mm/dd/yyy")&""),"Check Dates") -> Check Dates | H25: {=_xlfn.IFS(LEFT($C$22,8)="Sessions","Per Session", $C$22="DemoData1 Sessions", "Per Session",$C$22="PRODUCT2", "Per Session",$C$22="Per Hour", "Per Hour",$C$22="n/a", "Check Type",TRUE,"")} | I25: =IF(AND($C$23<>"",$C$24<>"",$C$25<>"",$C$22<>"PRODUCT2",ROUND(SUM($C$24*$C$25),2)=ROUND(SUM($C$23),2),OR(LEFT($C$22,8)="Sessions",LEFT($C$22,5)="DemoData1")),ROUND(SUM($C$23/20),2),IF(AND(LEFT($C$22,8)<>"Sessions",LEFT($C$22,5)<>"DemoData1",$C$25<>"",$C$23<>"",$C$24<>"",$C$22<>"PRODUCT2"),ROUND(SUM($C$25),2),IF(AND($C$23<>"",OR(LEFT($C$22,8)="Sessions",LEFT($C$22,5)="DemoData1")),ROUND(SUM($C$23/'Drop Down Lists'!$AV$2),2),IF(AND($C$25<>"",$C$24<>"",OR(LEFT($C$22,8)="Sessions",LEFT($C$22,5)="DemoData1")),ROUND(SUM($C$24*$C$25)/'Drop Down Lists'!$AV$2,2),IF(AND($C$25<>"",$C$22="Per Hour"),ROUND(SUM($C$25),2),IF(AND($C$22="PRODUCT2",$C$23<>""),ROUND(SUM($C$23/'Drop Down Lists'!$AV$2),2),IF(AND($C$23<>"",$C$24<>"",$C$22="Per Hour"),ROUND(SUM($C$23/$C$24),2),_xlfn.CONCAT("You need data! Check "&IF($C$23="",_xlfn.CONCAT(""&($A$23),IF(AND($C$24="",$C$25=""),_xlfn.CONCAT(", "&($A$23)&" & "&($A$25)&""),IF(OR($C$24="",$C$25=""),_xlfn.CONCAT(" & "&IF($C$24="",$A$24,$A$25))))),IF(AND($C$24="",$C$25=""),_xlfn.CONCAT(""&($A$24)&" & "&($A$25)&""),IF(OR($C$24="",$C$25=""),_xlfn.CONCAT(""&IF($C$24="",$A$24,$A$25))))))))))))) -> You need data! Check Revenue, Revenue & Number of Hours | J25: =IF($E$24="Yes", _xlfn.UNICHAR(9745),_xlfn.UNICHAR(9744)) -> ☐
A26: DemoData2 Configuration | H26: Link to CST | L26: {=_xlfn.IFS($C$14="LM7 - GENINTEGRATION 31",HYPERLINK("https://www.linkedin.com/in/jo-ann-balsamo","LM7 Developer Configuration"), $C$14="LMS8 - GENINTEGRATION 31", "LMS8 Client Response Collection", $C$14="LMS5 - GENINTEGRATION 31", "LMS5 Client Response Collection", $C$14="LMS6 - GENINTEGRATION 31", "LMS6 Client Response Collection",TRUE,"")} | M26: {=_xlfn.IFS($C$14="LM7 - GENINTEGRATION 31",HYPERLINK("https://www.linkedin.com/in/jo-ann-balsamo","https://www.linkedin.com/in/jo-ann-balsamo"), $C$14="LMS8 - GENINTEGRATION 31", "Update LMS9 / LMS8 Components 1-5 Once Response is Received from Client",$C$14="LMS5 - GENINTEGRATION 31", "Update LMS5 Components 1-6 Once Response is Received from Client",$C$14="LMS6 - GENINTEGRATION 31", "", TRUE,"")}
A27: DemoData2 Program ID | C27: 2026 | H27: DemoData2 Monthly Report CSM PRODCUT4: | I27: =TRIM(IFERROR(IF(AND('Program Contacts & Kickoff'!B2<>"",VLOOKUP('Program Contacts & Kickoff'!B2,'Program Contacts & Kickoff'!$I:$J,2,FALSE)<>""),VLOOKUP('Program Contacts & Kickoff'!B2,'Program Contacts & Kickoff'!$I:$J,2,FALSE),'Program Contacts & Kickoff'!E2),IF('Program Contacts & Kickoff'!B2<>"",'Program Contacts & Kickoff'!E2,""))) -> leah.adler@FakeDemoData.com | L27: {=_xlfn.IFS($C$14="LM7 - GENINTEGRATION 31","Username",$C$14="LMS5 - GENINTEGRATION 31","(1) LMS5 CID",$C$14="LMS8 - GENINTEGRATION 31",IF(F34="","DomPRODUCT4 n","Unique PRODUCT4"),$C$14="LMS6 - GENINTEGRATION 31", "(1) LMS6 Platform ID",TRUE,"")} | M27: {=_xlfn.IFS($C$14="LM7 - GENINTEGRATION 31","joann.balsamo@ PRODUCT4.com", $C$14="LMS5 - GENINTEGRATION 31", "= DemoData3 CID",$C$14="LMS8 - GENINTEGRATION 31", IF($F$34<>"",$F$34,"https://www.linkedin.com/in/jo-ann-balsamo"),$C$14="LMS6 - GENINTEGRATION 31", "= DemoData3 Issuer", TRUE,"")}
A28: DemoData727 | C28: NONCE-nonce-NONCE2-nonce3-nonce | H28: DemoData2 Monthly Report Sales PRODCUT4: | I28: =TRIM(IFERROR(IF(AND('Program Contacts & Kickoff'!B3<>"",VLOOKUP('Program Contacts & Kickoff'!B3,'Program Contacts & Kickoff'!$I:$J,2,FALSE)<>""),VLOOKUP('Program Contacts & Kickoff'!B3,'Program Contacts & Kickoff'!$I:$J,2,FALSE),'Program Contacts & Kickoff'!E3),IF('Program Contacts & Kickoff'!B3<>"",'Program Contacts & Kickoff'!E3,""))) -> gavin.park@FakeDemoData.com | L28: {=_xlfn.IFS($C$14="LM7 - GENINTEGRATION 31","PW", $C$14="LMS8 - GENINTEGRATION 31", "(1) LMS9 / LMS8 CID", $C$14="LMS5 - GENINTEGRATION 31", "(2) LMS5 Issuer", $C$14="LMS6 - GENINTEGRATION 31", "(2) LMS6 CID",TRUE,"")} | M28: {=_xlfn.IFS($C$14="LM7 - GENINTEGRATION 31","DemoData2023LATEST1$", $C$14="LMS5 - GENINTEGRATION 31", "= DemoData3 Issuer", $C$14="LMS8 - GENINTEGRATION 31", "= DemoData3 CID", $C$14="LMS6 - GENINTEGRATION 31", "= DemoData3 CID",TRUE,"")}
A29: Uppercase DemoData727 | C29: =UPPER(C28) -> NONCE-NONCE-NONCE2-NONCE3-NONCE | H29: {=_xlfn.IFS($C$14="LM7 - GENINTEGRATION 31","", $C$14="LMS8 - GENINTEGRATION 31", "", $C$14="LMS4", "X.509 Certificate File Name:", $C$14="LMS10", "X.509 Certificate File Name:", $C$14="LMS3", "LMS3 ID File Name:",TRUE,"")} | I29: {=_xlfn.IFS($C$14="LM7 - GENINTEGRATION 31","",$C$14="LMS8 - GENINTEGRATION 31","",$C$14="LMS4",IF(Concats!$A$8<>"",_xlfn.CONCAT(""&(SUBSTITUTE(UPPER(Concats!$A$8),"/",""))&"_LMS4_x509_Cert"),"Please Provide a PUBLIC DemoData2h"),$C$14="LMS10",IF(Concats!$A$8<>"",_xlfn.CONCAT(""&(SUBSTITUTE(UPPER(Concats!$A$8),"/",""))&"_GENINTEGRATION_x509_Cert"),"Please Provide a PUBLIC DemoData2h"),$C$14="LMS3",IF(Concats!$A$8<>"",_xlfn.CONCAT(""&(SUBSTITUTE(UPPER(Concats!$A$8),"/",""))&"_LMS3_ID"),"Please Provide a PUBLIC DemoData2h"),TRUE,"")} | L29: {=_xlfn.IFS($C$14="LM7 - GENINTEGRATION 31","Manual Registration >> Register a new Application", $C$14="LMS5 - GENINTEGRATION 31", "(3) LMS5 Public DemoData27set URL", $C$14="LMS8 - GENINTEGRATION 31", "(2) LMS9 / LMS8 DemoData27set URL", $C$14="LMS6 - GENINTEGRATION 31", "(3) LMS6 Deployment ID",TRUE,"")} | M29: {=_xlfn.IFS($C$14="LM7 - GENINTEGRATION 31","", $C$14="LMS8 - GENINTEGRATION 31", " = DemoData3 DemoData27set URL", $C$14="LMS5 - GENINTEGRATION 31", " = DemoData3 DemoData27set URL", $C$14="LMS6 - GENINTEGRATION 31", "= DemoData3 Deployment ID",TRUE,"")}
A30: {=_xlfn.IFS($C$14="LMS4", (HYPERLINK("https://www.linkedin.com/in/jo-ann-balsamo","X.509 Certificate:")), $C$14="LMS10",(HYPERLINK("https://www.linkedin.com/in/jo-ann-balsamo","x.509 Certificate:")),$C$14="LMS3",(HYPERLINK("https://www.linkedin.com/in/jo-ann-balsamo","LMS3 District ID:")), $C$14="LMS11","", TRUE, (HYPERLINK("https://www.linkedin.com/in/jo-ann-balsamo","DemoData27:")))} -> DemoData27: | C30: Nonce7 | H30: {=_xlfn.IFS($C$14="LM7 - GENINTEGRATION 31","LM7 Developer Application DemoData27", $C$14="LMS8 - GENINTEGRATION 31", "", $C$14="LMS4", "Link to Client X.509 File:", $C$14="LMS10", "Link to Client X.509 File:",$C$14="LMS3", "Link to LMS3 ID File:",TRUE,"")} | L30: {=_xlfn.IFS($C$14="LM7 - GENINTEGRATION 31","Application ID", $C$14="LMS5 - GENINTEGRATION 31", "(4) LMS5 Open ID Connect EP", $C$14="LMS8 - GENINTEGRATION 31", "(3) LMS9 / LMS8 OpenID Connect OA EP", $C$14="LMS6 - GENINTEGRATION 31", "(4) LMS6 Public DemoData27set URL",TRUE,"")} | M30: {=_xlfn.IFS($C$14="LM7 - GENINTEGRATION 31","Enter LM7 Developer Application ID-->", $C$14="LMS8 - GENINTEGRATION 31", "= DemoData3 ALU", $C$14="LMS5 - GENINTEGRATION 31", "= DemoData3 ALU", $C$14="LMS6 - GENINTEGRATION 31", "= DemoData3 DemoData27set URL",TRUE,"")}
A31: {=_xlfn.IFS($C$14="LMS4", "", $C$14="LMS3", "",$C$14="LMS11", "",$C$14="LMS10", "",TRUE, (HYPERLINK("https://www.linkedin.com/in/jo-ann-balsamo","DemoData72:")))} -> DemoData72: | C31: Nocne8 | H31: {=_xlfn.IFS($C$14="LM7 - GENINTEGRATION 31","LM7 Developer DemoData72", $C$14="LMS8 - GENINTEGRATION 31", "", TRUE,"")} | L31: {=_xlfn.IFS($C$14="LM7 - GENINTEGRATION 31","Application Name", $C$14="LMS5 - GENINTEGRATION 31", "(5) LMS5 Access Token URL", $C$14="LMS8 - GENINTEGRATION 31", "(4) LMS9 / LMS8 Issuer", $C$14="LMS6 - GENINTEGRATION 31", "(5) LMS6 Access Token URL",TRUE,"")} | M31: {=_xlfn.IFS($C$14="LM7 - GENINTEGRATION 31",_xlfn.CONCAT("DemoData.com "&UPPER(SUBSTITUTE(Concats!$A$8,"/",""))&" GENINTEGRATION 31"), $C$14="LMS5 - GENINTEGRATION 31", "NOT used in DemoData3 Build", $C$14="LMS8 - GENINTEGRATION 31", "= DemoData3 Issuer",$C$14="LMS6 - GENINTEGRATION 31", "NOT used in DemoData3 Build", TRUE,"")}
A32: Manual /PUBLIC/ Override: | D32: New ✨ The AUTO /PUBLIC/ will be used unless over-ridden with a manually entered /PUBLIC/ in C32; if not overriding the AUTO /PUBLIC/, this manual field can be left blank | L32: {=_xlfn.IFS($C$14="LM7 - GENINTEGRATION 31","Description", $C$14="LMS5 - GENINTEGRATION 31", "(6) LMS5 Deployment ID", $C$14="LMS8 - GENINTEGRATION 31", "(5) LMS9 / LMS8 Deployment ID", $C$14="LMS6 - GENINTEGRATION 31", "(6) LMS6 OA Request URL",TRUE,"")} | M32: {=_xlfn.IFS(C14="LM7 - GENINTEGRATION 31",IF(C8<>"",_xlfn.CONCAT("LM7 GENINTEGRATION 31 for DemoData.com and "&(SUBSTITUTE(SUBSTITUTE($C$8,"(",""),")",""))&""),"This component requires the Client/Program Name"),$C$14="LMS5 - GENINTEGRATION 31", "= DemoData3 Deployment ID", $C$14="LMS8 - GENINTEGRATION 31","=DemoData3 Deployment ID",$C$14="LMS6 - GENINTEGRATION 31", "= DemoData3 ALU",TRUE,"")}
A33: {=_xlfn.IFS($C$14="LMS4","",$C$14="LMS10","",C14="LMS3",(""),$C$14="LMS11","", TRUE,(HYPERLINK("https://www.linkedin.com/in/jo-ann-balsamo","DemoData3 Configuration")))} -> DemoData3 Configuration | C33: {=_xlfn.IFS($C$14="LMS4","",$C$14="LMS10","",C14="LMS3",(""),$C$14="LMS11","",TRUE,"DemoData3 Common Custom Parameters & Recommended Build Note configured on the DemoData3 CCP Tab ⬇️⬇️")} -> DemoData3 Common Custom Parameters & Recommended Build Note configured on the DemoData3 CCP Tab ⬇️⬇️ | H33: {=_xlfn.IFS($C$14="LMS4","",$C$14="LMS10","",C14="LMS3",(""),$C$14="LMS11","",TRUE,"Link to DemoData3 Common Custom Parameters")} -> Link to DemoData3 Common Custom Parameters | L33: {=IF(H34="",_xlfn.IFS($C$14="LM7 - GENINTEGRATION 31","DomPRODUCT4 n",$C$14="LMS8 - GENINTEGRATION 31","",$C$14="LMS1 - GENINTEGRATION 31 Link & Course NAV","",$C$14="LMS1 - GENINTEGRATION 31 - All Types of Placement","",TRUE,""),"Unique PRODUCT4")} -> Unique PRODUCT4 | M33: {=_xlfn.IFS($C$14="LM7 - GENINTEGRATION 31",IF($F$34="","api.DemoData3.com",RIGHT($F$34,21)),$C$14="LMS8 - GENINTEGRATION 31","",$C$14="LMS1 - GENINTEGRATION 31 Link & Course NAV","",$C$14="LMS1 - GENINTEGRATION 31 - All Types of Placement","",TRUE,"")}
A34: {=_xlfn.IFS($C$14="LMS4","",$C$14="LMS10","",$C$14="LMS3",(""),$C$14="LMS11","",TRUE,"Client URL:")} -> Client URL: | C34: https://www.linkedin.com/in/jo-ann-balsamo/ | E34: Unique PRODUCT4 (If Needed) | H34: Program Info for Unique PRODUCT4 Spreadsheet | I34: =IF(F34<>"",IF(AND($F$10<>"",$C$27<>""),(_xlfn.CONCAT($F$10)&" | "&($C$27)&" | "&($C$14)&" "&IF($I$2="GENINTEGRATION 31 Migration","Migration",_xlfn.CONCAT(" | "&($I$2)))&IF('Program Contacts & Kickoff'!B1<>"", _xlfn.CONCAT(" IM: "&('Program Contacts & Kickoff'!B1)&" | "&(TEXT(TODAY(),"YYYY-MM-DD"))&""),"")&" "&IF($C$35<>"",_xlfn.CONCAT("DemoData3 Property: "&($C$35)),"")&" "&IF($I$4<>"",_xlfn.CONCAT("JLB Ticket Link: "&($I$4)),"")),"This component requires a Unique PRODUCT4 and the Program Name & ID"),"") | L34: {=_xlfn.IFS($C$14="LM7 - GENINTEGRATION 31","My Inegration Supports (Toggle)", $C$14="LMS8 - GENINTEGRATION 31", "", $C$14="LMS1 - GENINTEGRATION 31 Link & Course NAV", "",$C$14="LMS1 - GENINTEGRATION 31 - All Types of Placement", "",TRUE,"")} | M34: {=_xlfn.IFS($C$14="LM7 - GENINTEGRATION 31","Enable GENINTEGRATION 31", $C$14="LMS8 - GENINTEGRATION 31", "", $C$14="LMS1 - GENINTEGRATION 31 Link & Course NAV", "", $C$14="LMS1 - GENINTEGRATION 31 - All Types of Placement", "",TRUE,"")}
A35: {=_xlfn.IFS($C$14="LMS4", "", $C$14="LMS3", "",$C$14="LMS10", "",$C$14="LMS11","",TRUE, "DemoData3 Property Link:")} -> DemoData3 Property Link: | C35: https://www.linkedin.com/in/jo-ann-balsamo/ | E35: DemoData3 Property Name: | F35: =IF(AND($F$10<>"",$C$27<>""),(_xlfn.CONCAT($F$10)&" | "&($C$27)),"This component requires the Program Name & the Program ID") -> DEMO | 2026 | G35: DemoData3 Name: | H35: =IF(AND(Concats!$A$8<>"",$C$14<>""),(_xlfn.CONCAT(UPPER(SUBSTITUTE(Concats!$A$8,"/","")))&" | "&($C$14)),"This component requires the PUBLIC & the Integration Method") -> LINKEDIN | LMS1 - GENINTEGRATION 31 Link & Course NAV | L35: {=_xlfn.IFS($C$14="LM7 - GENINTEGRATION 31","LI InitiPRODUCT4 tion URL", $C$14="LMS8 - GENINTEGRATION 31", "", $C$14="LMS1 - GENINTEGRATION 31 Link & Course NAV", "",$C$14="LMS1 - GENINTEGRATION 31 - All Types of Placement", "",TRUE,"")} | M35: {=_xlfn.IFS($C$14="LM7 - GENINTEGRATION 31",IF(C34<>"",C34,"This component requires the DemoData3 Client URL"), $C$14="LMS8 - GENINTEGRATION 31", "", $C$14="LMS1 - GENINTEGRATION 31 Link & Course NAV", "",$C$14="LMS1 - GENINTEGRATION 31 - All Types of Placement", "",TRUE,"")}
A36: {=_xlfn.IFS($C$14=0, "", $C$14="n/a", "", $C$14>0, IFERROR(VLOOKUP($C$14,'Drop Down Lists'!$B$4:$AO$63,2,FALSE),""))} -> GENINTEGRATION 31 Handler | C36: {=IFERROR(_xlfn.IFS($C$14=0,"",$C$14="n/a","",$C$14='Drop Down Lists'!B14,IFERROR(VLOOKUP($C$14,'Drop Down Lists'!$B$4:$AO$63,2,FALSE),"")),"")} | L36: Tool Redirect URL(s) | M36: =IF(C34<>"",C34,"This component requires the DemoData3 Client URL") -> https://www.linkedin.com/in/jo-ann-balsamo/
A37: {=_xlfn.IFS($C$14=0, "", $C$14="n/a", "", $C$14>0, IFERROR(VLOOKUP($C$14,'Drop Down Lists'!$B$4:$AO$63,3,FALSE),""))} -> GENINTEGRATION 31 Issuer | G37: {=TRIM(_xlfn.IFS($C$14=0,"",$C$14="n/a","",$C$14>0,IFERROR(VLOOKUP($C$14,'Drop Down Lists'!$B$4:$AO$63,4,FALSE),"This Component has not been configured yet")))} -> https://www.linkedin.com/in/jo-ann-balsamo | L37: Tool JWKS URL | M37: =IF(C34<>"",_xlfn.CONCAT(""&($C$34)&"/DemoData27set"&""),"This component requires the DemoData3 Client URL") -> https://www.linkedin.com/in/jo-ann-balsamo//DemoData27set
A38: {=_xlfn.IFS($C$14=0, "", $C$14="n/a", "", $C$14>0, IFERROR(VLOOKUP($C$14,'Drop Down Lists'!$B$4:$AO$63,5,FALSE),""))} -> CID | G38: {=TRIM(_xlfn.IFS($C$14=0,"",$C$14="n/a","",$C$14>0,IFERROR(VLOOKUP($C$14,'Drop Down Lists'!$B$4:$AO$63,6,FALSE),"")))} -> This component to be provided by the client | L38: Signing Algorithm | M38: RS256
A39: {=_xlfn.IFS($C$14=0, "", $C$14="n/a", "", $C$14>0, IFERROR(VLOOKUP($C$14,'Drop Down Lists'!$B$4:$AO$63,7,FALSE),""))} -> ALU | G39: {=TRIM(_xlfn.IFS($C$14=0,"",$C$14="n/a","",$C$14>0,IFERROR(VLOOKUP($C$14,'Drop Down Lists'!$B$4:$AO$63,8,FALSE),"This Component has not been configured yet")))} -> Please Selct an LMS Environment from the drop-down menu | L39: Manage Placements >> Register
A40: {=_xlfn.IFS($C$14=0, "", $C$14="n/a", "", $C$14>0, IFERROR(VLOOKUP($C$14,'Drop Down Lists'!$B$4:$AO$63,9,FALSE),""))} -> DemoData27 Set URL | G40: {=TRIM(_xlfn.IFS($C$14=0,"",$C$14="n/a","",$C$14>0,IFERROR(VLOOKUP($C$14,'Drop Down Lists'!$B$4:$AO$63,10,FALSE),"This Component has not been configured yet")))} -> Please Selct an LMS Environment from the drop-down menu | L40: Placement Name | M40: {=_xlfn.IFS($C$14="LM7 - GENINTEGRATION 31",_xlfn.CONCAT("DemoData.com "&UPPER(SUBSTITUTE(Concats!$A$8,"/",""))&" GENINTEGRATION 31"), $C$14="LMS8 - GENINTEGRATION 31", "= DemoData3 Deployment ID", TRUE,"")}
...

Sheet DemoData3 CCP Tab
A1: =IF('Program Config'!$C$14<>"",IF(AND('Program Config'!$C$14<>"LMS3",'Program Config'!$C$14<>"LMS4",'Program Config'!$C$14<>"LMS11",'Program Config'!$C$14<>"LMS10"),"DemoData3 Build Notes",""),"") -> DemoData3 Build Notes | C1: Go Back to Build Specs | E1: {=IF('Program Config'!$C$14<>"",IF(AND('Program Config'!$C$14<>"LMS3",'Program Config'!$C$14<>"LMS4",'Program Config'!$C$14<>"LMS11",'Program Config'!$C$14<>"LMS10"),_xlfn.IFS('Program Config'!$C$14="LMS1 - GENINTEGRATION 31 - All Types of Placement","GENINTEGRATION 22 Parameters",'Program Config'!$C$14="LMS1 - GENINTEGRATION 31 Link & Course NAV","GENINTEGRATION 22 Parameters",'Program Config'!$C$14="LMS8 - GENINTEGRATION 31","GENINTEGRATION 22 Parameters",'Program Config'!$C$14="LMS5 - GENINTEGRATION 31","GENINTEGRATION 22 Parameters",'Program Config'!$C$14="LMS2 - GENINTEGRATION 31","GENINTEGRATION 22 Parameters",'Program Config'!$C$14="LM7 - GENINTEGRATION 31","GENINTEGRATION 22 Parameters",'Program Config'!$C$14="LMS6 - GENINTEGRATION 31","GENINTEGRATION 22 Parameters",TRUE,"GENINTEGRATION 22 Attributes"),""),"")} -> GENINTEGRATION 22 Parameters | F1: {=_xlfn.IFS('Program Config'!$C$14="LMS1 - GENINTEGRATION 31 - All Types of Placement","LMS1 31 ClPRODUCT4 ms", 'Program Config'!$C$14="LMS1 - GENINTEGRATION 31 Link & Course NAV","LMS1 31 ClPRODUCT4 ms", 'Program Config'!$C$14="LMS5 - GENINTEGRATION 31","LMS5 31 ClPRODUCT4 ms", 'Program Config'!$C$14="LMS8 - GENINTEGRATION 31","LMS8 31 ClPRODUCT4 ms",'Program Config'!$C$14="LMS2 - GENINTEGRATION 31","LMS2 31 ClPRODUCT4 ms",'Program Config'!$C$14="LM7 - GENINTEGRATION 31","LM7 31 ClPRODUCT4 ms",'Program Config'!$C$14="LMS6 - GENINTEGRATION 31","LMS6 31 ClPRODUCT4 ms",TRUE,"")} -> LMS1 31 ClPRODUCT4 ms | H1: GENINTEGRATION 22 Parameters | I1: GENINTEGRATION 31 ClPRODUCT4 ms | J1: LM7 | K1: CV | L1: LMS8 | M1: MD | N1: CL | O1: JZ | P1: LM7 Matching | Q1: LM7 31 ClPRODUCT4 ms | R1: LMS1 Matching | S1: LMS1 31 ClPRODUCT4 ms | T1: LMS8 31 Matching | U1: LMS8 31 ClPRODUCT4 ms | V1: LMS6 31 Matching | W1: LMS6 31 ClPRODUCT4 ms | X1: LMS2 31 Matching | Y1: LMS2 31 ClPRODUCT4 ms | Z1: LMS5 31 Matching | AA1: LMS5 31 ClPRODUCT4 ms | AC1: Common Custom Parameters for GENINTEGRATION 22
A2: =IF('Program Config'!$C$14<>"",IF(AND('Program Config'!$C$14<>"LMS3",'Program Config'!$C$14<>"LMS4",'Program Config'!$C$14<>"LMS11",'Program Config'!$C$14<>"LMS10"),"DemoData3 Property Name",""),"") -> DemoData3 Property Name | B2: =IF('Program Config'!$C$14<>"",(IF(AND('Program Config'!$C$14<>"LMS3",'Program Config'!$C$14<>"LMS4",'Program Config'!$C$14<>"LMS11",'Program Config'!$C$14<>"LMS10"),IF(AND('Program Config'!$F$10<>"",'Program Config'!$C$27<>""),_xlfn.CONCAT('Program Config'!$F$10)&" | "&('Program Config'!$C$27),"This component requires the Program Name & the Program ID"),"This Build Configuration does not require an DemoData3")),"") -> DEMO | 2026 | E2: {=IFERROR(_xlfn.IFS($E$1="GENINTEGRATION 22 Parameters",(_xlfn.IFS($F$1=$Q$1,INDEX($P$2:$P$100,MATCH(0,INDEX(COUNTIF($E$1:$E1,$P$2:$P$100)+(COUNTIF($P$2:$P$100,$P$2:$P$100)<>1),0,0),0)),$F$1=$S$1,INDEX($R$2:$R$100,MATCH(0,INDEX(COUNTIF($E$1:$E1,$R$2:$R$100)+(COUNTIF($R$2:$R$100,$R$2:$R$100)<>1),0,0),0)),$F$1=$U$1,INDEX($T$2:$T$100,MATCH(0,INDEX(COUNTIF($E$1:$E1,$T$2:$T$100)+(COUNTIF($T$2:$T$100,$T$2:$T$100)<>1),0,0),0)),$F$1=$W$1,INDEX($V$2:$V$100,MATCH(0,INDEX(COUNTIF($E$1:$E1,$V$2:$V$100)+(COUNTIF($V$2:$V$100,$V$2:$V$100)<>1),0,0),0)),$F$1=$Y$1,INDEX($X$2:$X$100,MATCH(0,INDEX(COUNTIF($E$1:$E1,$X$2:$X$100)+(COUNTIF($X$2:$X$100,$X$2:$X$100)<>1),0,0),0)),$F$1=$AA$1,INDEX($Z$2:$Z$100,MATCH(0,INDEX(COUNTIF($E$1:$E1,$Z$2:$Z$100)+(COUNTIF($Z$2:$Z$100,$Z$2:$Z$100)<>1),0,0),0)),TRUE,"")),$E$1="GENINTEGRATION 22 Attributes",INDEX($H$2:$H$100,MATCH(0,INDEX(COUNTIF($E$1:$E1,$H$2:$H$100)+(COUNTIF($H$2:$H$100,$H$2:$H$100)<>1),0,0),0)),TRUE,""),"")} -> context_id | F2: {=IFERROR(_xlfn.IFS($F$1=$Q$1,_xlfn.XLOOKUP($E2,$P$2:$P$100,Q$2:Q$100)&"",$F$1=$S$1,_xlfn.XLOOKUP($E2,$R$2:$R$100,$S$2:$S$100)&"",$F$1=$Y$1,_xlfn.XLOOKUP($E2,$X$2:$X$100,$Y$2:$Y$100)&"",$F$1=$U$1,_xlfn.XLOOKUP($E2,$T$2:$T$100,$U$2:$U$100)&"",$F$1=$W$1,_xlfn.XLOOKUP($E2,$V$2:$V$100,$W$2:$W$100)&"",$F$1=$AA$1,_xlfn.XLOOKUP($E2,$Z$2:$Z$100,$AA$2:$AA$100)&"",TRUE, ""),"")} -> https://purl.demodata7.org/spec/GENINTEGRATION/clPRODUCT4 m/context|id | G2: {=IFERROR(IF($F2<>"",_xlfn.IFS($F$1="LM7 31 ClPRODUCT4 ms","LM7",$F$1="LMS1 31 ClPRODUCT4 ms","CV",$F$1="LMS2 31 ClPRODUCT4 ms","CL",$F$1="LMS5 31 ClPRODUCT4 ms","JZ",$F$1="LMS8 31 ClPRODUCT4 ms","DL",$F$1="LMS6 31 ClPRODUCT4 ms","MD",TRUE, ""),IF(AND($E$1="GENINTEGRATION 22 Attributes",$E2<>""),"22","")),"")} -> CV | H2: context_id | I2: https://purl.demodata7.org/spec/GENINTEGRATION/clPRODUCT4 m/context|id | J2: Yes | K2: Yes | L2: Yes | M2: Yes | N2: Yes | O2: Yes | P2: =IF(AND($H2<>"",Q2<>""),$H2,"") -> context_id | Q2: =IF($J2="yes",$I2,"") -> https://purl.demodata7.org/spec/GENINTEGRATION/clPRODUCT4 m/context|id | R2: =IF(AND($H2<>"",S2<>""),$H2,"") -> context_id | S2: =IF($K2="yes",$I2,"") -> https://purl.demodata7.org/spec/GENINTEGRATION/clPRODUCT4 m/context|id | T2: =IF(AND($H2<>"",U2<>""),$H2,"") -> context_id | U2: =IF($L2="yes",$I2,"") -> https://purl.demodata7.org/spec/GENINTEGRATION/clPRODUCT4 m/context|id | V2: =IF(AND($H2<>"",W2<>""),$H2,"") -> context_id | W2: =IF($M2="yes",$I2,"") -> https://purl.demodata7.org/spec/GENINTEGRATION/clPRODUCT4 m/context|id | X2: =IF(AND($H2<>"",Y2<>""),$H2,"") -> context_id | Y2: =IF($N2="yes",$I2,"") -> https://purl.demodata7.org/spec/GENINTEGRATION/clPRODUCT4 m/context|id | Z2: =IF(AND($H2<>"",AA2<>""),$H2,"") -> context_id | AA2: =IF($L2="yes",$I2,"") -> https://purl.demodata7.org/spec/GENINTEGRATION/clPRODUCT4 m/context|id | AC2: Copy Context Title to Context ID
A3: =IF('Program Config'!$C$14<>"",IF(AND('Program Config'!$C$14<>"LMS3",'Program Config'!$C$14<>"LMS4",'Program Config'!$C$14<>"LMS11",'Program Config'!$C$14<>"LMS10"),"Adapter Name",""),"") -> Adapter Name | B3: =IF('Program Config'!$C$14<>"",IF(AND('Program Config'!$C$14<>"LMS3",'Program Config'!$C$14<>"LMS4",'Program Config'!$C$14<>"LMS11",'Program Config'!$C$14<>"LMS10"),IF(AND(Concats!$A$8<>"",'Program Config'!$C$14<>""),(_xlfn.CONCAT(UPPER(SUBSTITUTE(Concats!$A$8,"/","")))&" | "&('Program Config'!$C$14)),"This component requires the PUBLIC & the Integration Method"),""),"") -> LINKEDIN | LMS1 - GENINTEGRATION 31 Link & Course NAV | E3: {=IFERROR(_xlfn.IFS($E$1="GENINTEGRATION 22 Parameters",(_xlfn.IFS($F$1=$Q$1,INDEX($P$2:$P$100,MATCH(0,INDEX(COUNTIF($E$1:$E2,$P$2:$P$100)+(COUNTIF($P$2:$P$100,$P$2:$P$100)<>1),0,0),0)),$F$1=$S$1,INDEX($R$2:$R$100,MATCH(0,INDEX(COUNTIF($E$1:$E2,$R$2:$R$100)+(COUNTIF($R$2:$R$100,$R$2:$R$100)<>1),0,0),0)),$F$1=$U$1,INDEX($T$2:$T$100,MATCH(0,INDEX(COUNTIF($E$1:$E2,$T$2:$T$100)+(COUNTIF($T$2:$T$100,$T$2:$T$100)<>1),0,0),0)),$F$1=$W$1,INDEX($V$2:$V$100,MATCH(0,INDEX(COUNTIF($E$1:$E2,$V$2:$V$100)+(COUNTIF($V$2:$V$100,$V$2:$V$100)<>1),0,0),0)),$F$1=$Y$1,INDEX($X$2:$X$100,MATCH(0,INDEX(COUNTIF($E$1:$E2,$X$2:$X$100)+(COUNTIF($X$2:$X$100,$X$2:$X$100)<>1),0,0),0)),$F$1=$AA$1,INDEX($Z$2:$Z$100,MATCH(0,INDEX(COUNTIF($E$1:$E2,$Z$2:$Z$100)+(COUNTIF($Z$2:$Z$100,$Z$2:$Z$100)<>1),0,0),0)),TRUE,"")),$E$1="GENINTEGRATION 22 Attributes",INDEX($H$2:$H$100,MATCH(0,INDEX(COUNTIF($E$1:$E2,$H$2:$H$100)+(COUNTIF($H$2:$H$100,$H$2:$H$100)<>1),0,0),0)),TRUE,""),"")} -> context_label | F3: {=IFERROR(_xlfn.IFS($F$1=$Q$1,_xlfn.XLOOKUP($E3,$P$2:$P$100,Q$2:Q$100)&"",$F$1=$S$1,_xlfn.XLOOKUP($E3,$R$2:$R$100,$S$2:$S$100)&"",$F$1=$Y$1,_xlfn.XLOOKUP($E3,$X$2:$X$100,$Y$2:$Y$100)&"",$F$1=$U$1,_xlfn.XLOOKUP($E3,$T$2:$T$100,$U$2:$U$100)&"",$F$1=$W$1,_xlfn.XLOOKUP($E3,$V$2:$V$100,$W$2:$W$100)&"",$F$1=$AA$1,_xlfn.XLOOKUP($E3,$Z$2:$Z$100,$AA$2:$AA$100)&"",TRUE, ""),"")} -> https://purl.demodata7.org/spec/GENINTEGRATION/clPRODUCT4 m/context|label | G3: {=IFERROR(IF($F3<>"",_xlfn.IFS($F$1="LM7 31 ClPRODUCT4 ms","LM7",$F$1="LMS1 31 ClPRODUCT4 ms","CV",$F$1="LMS2 31 ClPRODUCT4 ms","CL",$F$1="LMS5 31 ClPRODUCT4 ms","JZ",$F$1="LMS8 31 ClPRODUCT4 ms","DL",$F$1="LMS6 31 ClPRODUCT4 ms","MD",TRUE, ""),IF(AND($E$1="GENINTEGRATION 22 Attributes",$E3<>""),"22","")),"")} -> CV | H3: context_label | I3: https://purl.demodata7.org/spec/GENINTEGRATION/clPRODUCT4 m/context|label | J3: Yes | K3: Yes | L3: Yes | M3: Yes | N3: Yes | O3: Yes | P3: =IF(AND($H3<>"",Q3<>""),$H3,"") -> context_label | Q3: =IF($J3="yes",$I3,"") -> https://purl.demodata7.org/spec/GENINTEGRATION/clPRODUCT4 m/context|label | R3: =IF(AND($H3<>"",S3<>""),$H3,"") -> context_label | S3: =IF($K3="yes",$I3,"") -> https://purl.demodata7.org/spec/GENINTEGRATION/clPRODUCT4 m/context|label | T3: =IF(AND($H3<>"",U3<>""),$H3,"") -> context_label | U3: =IF($L3="yes",$I3,"") -> https://purl.demodata7.org/spec/GENINTEGRATION/clPRODUCT4 m/context|label | V3: =IF(AND($H3<>"",W3<>""),$H3,"") -> context_label | W3: =IF($M3="yes",$I3,"") -> https://purl.demodata7.org/spec/GENINTEGRATION/clPRODUCT4 m/context|label | X3: =IF(AND($H3<>"",Y3<>""),$H3,"") -> context_label | Y3: =IF($N3="yes",$I3,"") -> https://purl.demodata7.org/spec/GENINTEGRATION/clPRODUCT4 m/context|label | Z3: =IF(AND($H3<>"",AA3<>""),$H3,"") -> context_label | AA3: =IF($L3="yes",$I3,"") -> https://purl.demodata7.org/spec/GENINTEGRATION/clPRODUCT4 m/context|label | AC3: From | AD3: context_title
A4: =IF('Program Config'!$C$14<>"",IF(AND('Program Config'!$C$14<>"LMS3",'Program Config'!$C$14<>"LMS4",'Program Config'!$C$14<>"LMS11",'Program Config'!$C$14<>"LMS10"),"Recommended DemoData3 Build Settings Note",""),"") -> Recommended DemoData3 Build Settings Note | B4: =TRIM(IF('Program Config'!$C$14<>"",IF(AND('Program Config'!$C$14<>"LMS3",'Program Config'!$C$14<>"LMS4",'Program Config'!$C$14<>"LMS11",'Program Config'!$C$14<>"LMS10"),IF(AND('Program Config'!$C$27<>"",'Program Config'!$H$2<>"",'Program Config'!$C$14<>""),_xlfn.CONCAT("")&IF('Program Config'!$F$10<>"",_xlfn.CONCAT(""&('Program Config'!$F$10)&"",_xlfn.CONCAT(" | Program ID "&('Program Config'!$C$27)&" | "&('Program Config'!$H$2)&IF('Program Config'!$C$14<>"",_xlfn.CONCAT(" | "&('Program Config'!$C$14),"")&IF('Program Contacts & Kickoff'!$B$1<>"",_xlfn.CONCAT(" | IM: "&(VLOOKUP('Program Contacts & Kickoff'!$B$1,'Program Contacts & Kickoff'!$O$2:$Q$475,1,TRUE)&""),""))))))&IF('Program Config'!$H$3<>"",_xlfn.CONCAT(" Build Specs View-Only Link: "&('Program Config'!$H$3)),"")&IF('Program Config'!$F$34<>"",_xlfn.CONCAT(" LMS Required Unique DomPRODUCT4 n: "&('Program Config'!$F$34)),"")&IF('Program Config'!$H$4<>"",_xlfn.CONCAT(" JSM Ticket Link: "&('Program Config'!$H$4)),"")&IF('Program Config'!$H$2="GENINTEGRATION 31 Migration",_xlfn.CONCAT(" Team IM Migration Project Link: "&"https://www.linkedin.com/in/jo-ann-balsamo"),""),"Get to Building! 🔨 🛠️ 🔧 This program has not been configured yet."),"This is true for: • LMS3 Integrations • LMS4 Integrations • LMS10 Integrations • LMS11 Programs"),"")) -> DEMO | Program ID 2026 | New Build | LMS1 - GENINTEGRATION 31 Link & Course NAV | IM: Clara Doyle Build Specs View-Only Link: https://www.linkedin.com/in/jo-ann-balsamo/ | E4: {=IFERROR(_xlfn.IFS($E$1="GENINTEGRATION 22 Parameters",(_xlfn.IFS($F$1=$Q$1,INDEX($P$2:$P$100,MATCH(0,INDEX(COUNTIF($E$1:$E3,$P$2:$P$100)+(COUNTIF($P$2:$P$100,$P$2:$P$100)<>1),0,0),0)),$F$1=$S$1,INDEX($R$2:$R$100,MATCH(0,INDEX(COUNTIF($E$1:$E3,$R$2:$R$100)+(COUNTIF($R$2:$R$100,$R$2:$R$100)<>1),0,0),0)),$F$1=$U$1,INDEX($T$2:$T$100,MATCH(0,INDEX(COUNTIF($E$1:$E3,$T$2:$T$100)+(COUNTIF($T$2:$T$100,$T$2:$T$100)<>1),0,0),0)),$F$1=$W$1,INDEX($V$2:$V$100,MATCH(0,INDEX(COUNTIF($E$1:$E3,$V$2:$V$100)+(COUNTIF($V$2:$V$100,$V$2:$V$100)<>1),0,0),0)),$F$1=$Y$1,INDEX($X$2:$X$100,MATCH(0,INDEX(COUNTIF($E$1:$E3,$X$2:$X$100)+(COUNTIF($X$2:$X$100,$X$2:$X$100)<>1),0,0),0)),$F$1=$AA$1,INDEX($Z$2:$Z$100,MATCH(0,INDEX(COUNTIF($E$1:$E3,$Z$2:$Z$100)+(COUNTIF($Z$2:$Z$100,$Z$2:$Z$100)<>1),0,0),0)),TRUE,"")),$E$1="GENINTEGRATION 22 Attributes",INDEX($H$2:$H$100,MATCH(0,INDEX(COUNTIF($E$1:$E3,$H$2:$H$100)+(COUNTIF($H$2:$H$100,$H$2:$H$100)<>1),0,0),0)),TRUE,""),"")} -> context_title | F4: {=IFERROR(_xlfn.IFS($F$1=$Q$1,_xlfn.XLOOKUP($E4,$P$2:$P$100,Q$2:Q$100)&"",$F$1=$S$1,_xlfn.XLOOKUP($E4,$R$2:$R$100,$S$2:$S$100)&"",$F$1=$Y$1,_xlfn.XLOOKUP($E4,$X$2:$X$100,$Y$2:$Y$100)&"",$F$1=$U$1,_xlfn.XLOOKUP($E4,$T$2:$T$100,$U$2:$U$100)&"",$F$1=$W$1,_xlfn.XLOOKUP($E4,$V$2:$V$100,$W$2:$W$100)&"",$F$1=$AA$1,_xlfn.XLOOKUP($E4,$Z$2:$Z$100,$AA$2:$AA$100)&"",TRUE, ""),"")} -> https://purl.demodata7.org/spec/GENINTEGRATION/clPRODUCT4 m/context|title | G4: {=IFERROR(IF($F4<>"",_xlfn.IFS($F$1="LM7 31 ClPRODUCT4 ms","LM7",$F$1="LMS1 31 ClPRODUCT4 ms","CV",$F$1="LMS2 31 ClPRODUCT4 ms","CL",$F$1="LMS5 31 ClPRODUCT4 ms","JZ",$F$1="LMS8 31 ClPRODUCT4 ms","DL",$F$1="LMS6 31 ClPRODUCT4 ms","MD",TRUE, ""),IF(AND($E$1="GENINTEGRATION 22 Attributes",$E4<>""),"22","")),"")} -> CV | H4: context_title | I4: https://purl.demodata7.org/spec/GENINTEGRATION/clPRODUCT4 m/context|title | J4: Yes | K4: Yes | L4: Yes | M4: Yes | N4: Yes | O4: Yes | P4: =IF(AND($H4<>"",Q4<>""),$H4,"") -> context_title | Q4: =IF($J4="yes",$I4,"") -> https://purl.demodata7.org/spec/GENINTEGRATION/clPRODUCT4 m/context|title | R4: =IF(AND($H4<>"",S4<>""),$H4,"") -> context_title | S4: =IF($K4="yes",$I4,"") -> https://purl.demodata7.org/spec/GENINTEGRATION/clPRODUCT4 m/context|title | T4: =IF(AND($H4<>"",U4<>""),$H4,"") -> context_title | U4: =IF($L4="yes",$I4,"") -> https://purl.demodata7.org/spec/GENINTEGRATION/clPRODUCT4 m/context|title | V4: =IF(AND($H4<>"",W4<>""),$H4,"") -> context_title | W4: =IF($M4="yes",$I4,"") -> https://purl.demodata7.org/spec/GENINTEGRATION/clPRODUCT4 m/context|title | X4: =IF(AND($H4<>"",Y4<>""),$H4,"") -> context_title | Y4: =IF($N4="yes",$I4,"") -> https://purl.demodata7.org/spec/GENINTEGRATION/clPRODUCT4 m/context|title | Z4: =IF(AND($H4<>"",AA4<>""),$H4,"") -> context_title | AA4: =IF($L4="yes",$I4,"") -> https://purl.demodata7.org/spec/GENINTEGRATION/clPRODUCT4 m/context|title | AC4: To | AD4: context_id
E5: {=IFERROR(_xlfn.IFS($E$1="GENINTEGRATION 22 Parameters",(_xlfn.IFS($F$1=$Q$1,INDEX($P$2:$P$100,MATCH(0,INDEX(COUNTIF($E$1:$E4,$P$2:$P$100)+(COUNTIF($P$2:$P$100,$P$2:$P$100)<>1),0,0),0)),$F$1=$S$1,INDEX($R$2:$R$100,MATCH(0,INDEX(COUNTIF($E$1:$E4,$R$2:$R$100)+(COUNTIF($R$2:$R$100,$R$2:$R$100)<>1),0,0),0)),$F$1=$U$1,INDEX($T$2:$T$100,MATCH(0,INDEX(COUNTIF($E$1:$E4,$T$2:$T$100)+(COUNTIF($T$2:$T$100,$T$2:$T$100)<>1),0,0),0)),$F$1=$W$1,INDEX($V$2:$V$100,MATCH(0,INDEX(COUNTIF($E$1:$E4,$V$2:$V$100)+(COUNTIF($V$2:$V$100,$V$2:$V$100)<>1),0,0),0)),$F$1=$Y$1,INDEX($X$2:$X$100,MATCH(0,INDEX(COUNTIF($E$1:$E4,$X$2:$X$100)+(COUNTIF($X$2:$X$100,$X$2:$X$100)<>1),0,0),0)),$F$1=$AA$1,INDEX($Z$2:$Z$100,MATCH(0,INDEX(COUNTIF($E$1:$E4,$Z$2:$Z$100)+(COUNTIF($Z$2:$Z$100,$Z$2:$Z$100)<>1),0,0),0)),TRUE,"")),$E$1="GENINTEGRATION 22 Attributes",INDEX($H$2:$H$100,MATCH(0,INDEX(COUNTIF($E$1:$E4,$H$2:$H$100)+(COUNTIF($H$2:$H$100,$H$2:$H$100)<>1),0,0),0)),TRUE,""),"")} -> context_type | F5: {=IFERROR(_xlfn.IFS($F$1=$Q$1,_xlfn.XLOOKUP($E5,$P$2:$P$100,Q$2:Q$100)&"",$F$1=$S$1,_xlfn.XLOOKUP($E5,$R$2:$R$100,$S$2:$S$100)&"",$F$1=$Y$1,_xlfn.XLOOKUP($E5,$X$2:$X$100,$Y$2:$Y$100)&"",$F$1=$U$1,_xlfn.XLOOKUP($E5,$T$2:$T$100,$U$2:$U$100)&"",$F$1=$W$1,_xlfn.XLOOKUP($E5,$V$2:$V$100,$W$2:$W$100)&"",$F$1=$AA$1,_xlfn.XLOOKUP($E5,$Z$2:$Z$100,$AA$2:$AA$100)&"",TRUE, ""),"")} -> https://purl.demodata7.org/spec/GENINTEGRATION/clPRODUCT4 m/context|type | G5: {=IFERROR(IF($F5<>"",_xlfn.IFS($F$1="LM7 31 ClPRODUCT4 ms","LM7",$F$1="LMS1 31 ClPRODUCT4 ms","CV",$F$1="LMS2 31 ClPRODUCT4 ms","CL",$F$1="LMS5 31 ClPRODUCT4 ms","JZ",$F$1="LMS8 31 ClPRODUCT4 ms","DL",$F$1="LMS6 31 ClPRODUCT4 ms","MD",TRUE, ""),IF(AND($E$1="GENINTEGRATION 22 Attributes",$E5<>""),"22","")),"")} -> CV | H5: context_type | I5: https://purl.demodata7.org/spec/GENINTEGRATION/clPRODUCT4 m/context|type | J5: Yes | K5: Yes | L5: Yes | M5: Yes | N5: Yes | O5: Yes | P5: =IF(AND($H5<>"",Q5<>""),$H5,"") -> context_type | Q5: =IF($J5="yes",$I5,"") -> https://purl.demodata7.org/spec/GENINTEGRATION/clPRODUCT4 m/context|type | R5: =IF(AND($H5<>"",S5<>""),$H5,"") -> context_type | S5: =IF($K5="yes",$I5,"") -> https://purl.demodata7.org/spec/GENINTEGRATION/clPRODUCT4 m/context|type | T5: =IF(AND($H5<>"",U5<>""),$H5,"") -> context_type | U5: =IF($L5="yes",$I5,"") -> https://purl.demodata7.org/spec/GENINTEGRATION/clPRODUCT4 m/context|type | V5: =IF(AND($H5<>"",W5<>""),$H5,"") -> context_type | W5: =IF($M5="yes",$I5,"") -> https://purl.demodata7.org/spec/GENINTEGRATION/clPRODUCT4 m/context|type | X5: =IF(AND($H5<>"",Y5<>""),$H5,"") -> context_type | Y5: =IF($N5="yes",$I5,"") -> https://purl.demodata7.org/spec/GENINTEGRATION/clPRODUCT4 m/context|type | Z5: =IF(AND($H5<>"",AA5<>""),$H5,"") -> context_type | AA5: =IF($L5="yes",$I5,"") -> https://purl.demodata7.org/spec/GENINTEGRATION/clPRODUCT4 m/context|type | AC5: Copy PRODCUT4 to user_id
